File: docs/source/examples/magdata.dat
[Header]
; MPMS3 Data File (default extension .dat)
; Copyright (c) 2007, Quantum Design, Inc. All rights reserved.

This is an example Quantum Design data file. The data was generated with:
MagentroData.sim_data(np.linspace(1., 100., 100), np.linspace(20., 100., 5), sigma_m=5e-5, random_seed=0)

... (other info)

INFO,0.10,SAMPLE_MASS

... (other info)

[Data]
Comment,Temperature (K),Magnetic Field (Oe),Moment (emu),M. Std. Err. (emu)
,1.0000001257302211,20.00000129289305,0.002023237620999843,5e-05
,1.9999998678951367,20.000000453671266,0.001977035133203755,5e-05
,3.0000006404226505,19.999998309840056,0.0019691176468353954,5e-05
,4.000000104900117,19.999999271804974,0.0019703462809422924,5e-05
,4.999999464330627,20.000001232303404,0.0018861314508571284,5e-05
,6.000000361595055,20.000000298335245,0.0019322008810676505,5e-05
,7.000001304000045,19.999999990141063,0.0019009373434497143,5e-05
,8.000000947080963,20.000000441200594,0.0019555461883546247,5e-05
,8.999999296264765,20.00000072104895,0.0019152194059520718,5e-05
,9.99999873457853,19.999999291534763,0.0019367815210710388,5e-05
,10.999999376725537,19.99999970959992,0.0019315002855361302,5e-05
,12.000000041325979,20.00000014291365,0.001929736707017919,5e-05
,12.999997674969226,19.99999945604228,0.0019258136002359494,5e-05
,13.999999781208336,19.999999866548443,0.0018907299688582751,5e-05
,14.999998754089052,20.000001297871762,0.0018662471784268993,5e-05
,15.999999267732646,19.999999032180135,0.0018811287696867737,5e-05
,16.999999455741015,20.00000192666271,0.001963126289986999,5e-05
,17.999999683699844,20.000001879344378,0.001923269366757648,5e-05
,19.000000411630538,19.99999828656056,0.0019287391021024737,5e-05
,20.000001042513368,19.999999858977336,0.0019630510172119003,5e-05
,20.999999871465338,20.00000034269157,0.00182959133686584,5e-05
,22.000001366463472,19.99999923912891,0.0019084428168062522,5e-05
,22.999999334805327,19.999999258919495,0.0018234749315201469,5e-05
,24.00000035151007,19.999999762584302,0.0018547323252625597,5e-05
,25.00000090347018,20.000000739178088,0.001889861196084718,5e-05
,26.000000094012297,19.999999488666163,0.0019405975770654701,5e-05
,26.99999925650075,20.00000182669381,0.0018150933235283838,5e-05
,27.999999078274623,20.000000289974004,0.0018439411467899344,5e-05
,28.999999542274175,19.999999897424715,0.0019012071693855026,5e-05
,30.000000220195123,20.000001449259685,0.0017639399303085003,5e-05
,30.999998990381815,20.000000626281196,0.0018519857641140704,5e-05
,31.999999790824425,20.000000369286777,0.0018144327449810538,5e-05
,32.99999984077499,19.999999668859616,0.0017823540056812295,5e-05
,34.00000054084558,20.000001813985612,0.0018311022211315617,5e-05
,35.000000214659124,20.00000081182159,0.0018517065947080366,5e-05
,36.00000035537271,19.999999796588664,0.001775521847090231,5e-05
,36.99999934617139,19.99999842280085,0.001840387606834219,5e-05
,37.99999987038637,20.000000372951543,0.0018315259433903735,5e-05
,39.00000078397547,19.999998856259907,0.001763549328159344,5e-05
,40.00000149343114,19.999998284054048,0.001907499544492146,5e-05
,40.999998740934466,19.999999720848493,0.0018899961771460855,5e-05
,42.00000151392378,20.000000281471102,0.0017997163033969111,5e-05
,43.000001345875425,20.000001282481232,0.0018221632461232595,5e-05
,44.0000007813114,20.000000282451825,0.00190038808733795,5e-05
,45.00000026445563,20.00000080601953,0.0018489709518430767,5e-05
,45.99999968607719,19.999998774117294,0.0017951223133183055,5e-05
,47.000001458020684,19.999999977467823,0.0019542775391040183,5e-05
,48.00000196025832,20.00000012421132,0.001918204819731002,5e-05
,49.00000180163487,20.000000862246186,0.0020300586905778314,5e-05
,50.000001315103766,20.000000116060672,0.0019702888519171386,5e-05
,51.00000035738041,20.000000804078958,0.00198015261193525,5e-05
,51.99999879168137,19.99999949580075,0.002132665560309463,5e-05
,52.99999999554586,20.000000357954907,0.0019984666521083564,5e-05
,54.00000065647494,20.000000414866403,0.001976968503373129,5e-05
,54.99999871163853,19.999998750224275,0.0020524681940927414,5e-05
,56.00000039512206,20.000000175538627,0.002112744154612419,5e-05
,57.0000004298637,19.999999679637472,0.0020106848899441045,5e-05
,58.000000696042726,19.99999809591205,0.002034082995394231,5e-05
,58.99999881588203,20.00000095840668,0.0021096530571096173,5e-05
,59.99999933829743,19.99999963814132,0.0019316368436959662,5e-05
,60.99999956356475,19.99999914760994,0.002037469510442308,5e-05
,61.999998830198095,19.999999622683255,0.0021283621687428578,5e-05
,63.000001739367875,20.000000138200303,0.00205129440131804,5e-05
,63.999999504089274,20.000001507909484,0.0019866399833619757,5e-05
,65.00000032896963,19.9999998340668,0.002146659132394079,5e-05
,65.99999974142746,20.000000472407496,0.00195721949065153,5e-05
,67.00000158347288,20.000001373579376,0.0019738317226520048,5e-05
,68.000001320361,20.00000053355053,0.0019485221571159163,5e-05
,69.00000063335263,20.000001068564156,0.0019334740880985327,5e-05
,69.99999779649012,19.999999523490143,0.0018681699243472507,5e-05
,71.00000005202898,20.000000771049326,0.0018353392274310268,5e-05
,72.0000006836862,19.999999942024,0.00179073016582594,5e-05
,73.00000100396157,20.000001074411237,0.0017280879848528866,5e-05
,73.99999938209295,19.99999899644043,0.0016781758944463617,5e-05
,75.00000182201137,19.99999922044225,0.001492649444305252,5e-05
,75.99999867956903,20.000001268731573,0.0015692280087285522,5e-05
,76.99999933847198,19.999999803916026,0.0014105514614311575,5e-05
,78.00000093504998,19.999999641039352,0.0013045986588366438,5e-05
,79.00000004905462,20.00000007757242,0.0014132496653616153,5e-05
,80.00000200239258,19.99999931050254,0.001210780792317292,5e-05
,81.0000001885192,20.00000133194137,0.001215056641464495,5e-05
,81.99999936680591,19.99999875083735,0.0010990560674165228,5e-05
,82.99999962243649,19.999999849402002,0.0010364433034628813,5e-05
,83.99999890885388,20.000000346952785,0.001028699672745867,5e-05
,84.99999872231983,19.999999895552932,0.0008880846502886606,5e-05
,86.00000063041149,19.999999197712455,0.0008972492354175588,5e-05
,87.0000005811658,19.999999131610803,0.0008381718257858452,5e-05
,88.00000129455881,20.000000425394425,0.0008204936210628491,5e-05
,88.9999992453942,19.99999896951955,0.0006913668524915474,5e-05
,90.00000168910745,20.000000646242707,0.0007092965870908097,5e-05
,90.9999997126123,19.999998475851637,0.0006947415323404974,5e-05
,92.00000157440827,19.999999445016904,0.0006427531281930695,5e-05
,92.99999956721415,20.000000036306023,0.0005503935001080217,5e-05
,93.9999992645167,19.999998747848057,0.0005041290875508768,5e-05
,95.00000024978537,20.000000652010865,0.0005875585599409679,5e-05
,96.00000103145308,19.999999981461187,0.0005228431182199042,5e-05
,97.00000016100958,19.99999896392632,0.0003416659872034834,5e-05
,97.99999941447118,19.99999848111177,0.00039741993633898593,5e-05
,98.99999865878029,19.999998434410628,0.00035491607812901795,5e-05
,99.99999859847979,20.000000051033947,0.0003041957411412675,5e-05
,1.0000005026828498,39.99999884316989,0.003935922835346792,5e-05
,2.0000009897130333,39.9999986351204,0.003948305683992019,5e-05
,2.9999998357054074,39.99999976877407,0.003966200299897189,5e-05
,3.9999989256351416,40.00000227750053,0.003925434418788344,5e-05
,5.000000873042152,40.00000027754036,0.003926388344273095,5e-05
,5.999998719606055,40.00000076291883,0.003973640171920654,5e-05
,6.999999286931905,40.00000021271835,0.003914279341953162,5e-05
,8.000000621017854,40.00000078298216,0.003919725922564134,5e-05
,8.999997749858826,39.99999865691135,0.003935786824508024,5e-05
,10.000000386369598,39.99999956948803,0.003961458390639879,5e-05
,10.999999418359163,40.00000026135085,0.0039343902203594,5e-05
,12.000000109279698,39.99999998208318,0.0038848720257080543,5e-05
,12.999999924298473,39.99999980800678,0.0038691169302354955,5e-05
,14.000000202114395,39.99999933412392,0.0037900191682434517,5e-05
,15.000000694171936,39.9999997416169,0.0038580561057378906,5e-05
,15.999999241630249,39.99999922580218,0.0037836569151337013,5e-05
,17.000001420982024,39.99999757816698,0.0037762198028363685,5e-05
,18.000000726093788,39.99999880549156,0.003851740008958649,5e-05
,19.00000084373266,40.00000047565294,0.0038059150965082263,5e-05
,20.00000116486398,40.00000155707796,0.0038262785998115227,5e-05
,21.00000078758822,40.00000181358017,0.0037631051383976576,5e-05
,22.00000084407868,40.00000009675174,0.003846433777962086,5e-05
,23.00000007559361,40.00000089338362,0.0037856991456968925,5e-05
,23.99999857322615,40.00000090797791,0.003830338829072663,5e-05
,24.9999998649549,39.999999307740815,0.003797465015678983,5e-05
,25.99999923048536,39.99999830206017,0.003765392516407779,5e-05
,26.999998577258232,40.00000003088732,0.0037271370950703944,5e-05
,28.00000025845279,39.999998237799005,0.003747268036929718,5e-05
,28.999999431450547,39.99999968007039,0.0037825144061669337,5e-05
,29.999998970195563,40.000000608117084,0.0037722997609629734,5e-05
,30.99999895699892,39.99999857993051,0.0036749019682549328,5e-05
,32.00000026841708,40.00000003229538,0.0037842563612465116,5e-05
,33.00000035867195,40.000001240018115,0.003721641633509394,5e-05
,34.00000132245747,40.00000036151248,0.0037735628851128214,5e-05
,34.999999986085335,40.0000005223217,0.0036994828294775683,5e-05
,36.00000104183976,40.00000090674041,0.003768867927805839,5e-05
,37.00000140226483,40.00000173296307,0.003700753914195116,5e-05
,38.00000115016564,40.00000015142308,0.003751541196269907,5e-05
,38.99999763469609,40.00000122950086,0.0037353924513345597,5e-05
,40.00000122868372,39.999999935830786,0.003741771994031367,5e-05
,41.00000033962001,39.99999945383119,0.0037337744413716276,5e-05
,42.000000423771354,40.00000031482097,0.0037604900667241206,5e-05
,43.000000371227415,39.99999939418715,0.00368688654169562,5e-05
,44.00000038275716,39.99999942687079,0.0038228126949357566,5e-05
,45.00000031941422,39.99999939225937,0.00383104100881615,5e-05
,45.99999964108669,39.999997704575804,0.003763264517882444,5e-05
,46.9999980983647,40.00000010549948,0.003716873068718682,5e-05
,47.999999891085274,39.99999873616464,0.003751515961776013,5e-05
,48.99999919626815,39.99999989273088,0.0038262703576980965,5e-05
,50.000001080163415,40.00000144996878,0.003801768554845258,5e-05
,50.99999971123349,39.999999478999676,0.003743172492588873,5e-05
,52.000000083475356,39.99999945799084,0.0037864003566953843,5e-05
,52.999999150394046,40.000001363909384,0.0036680465470519436,5e-05
,53.99999948937753,40.00000054630576,0.003662944164209688,5e-05
,54.99999998846694,40.0000009765271,0.0036853220302699155,5e-05
,55.999998514624814,39.999999644708765,0.0036191245489622824,5e-05
,57.000000300685116,40.00000074808321,0.0035509240450353756,5e-05
,57.99999989392774,39.99999931383141,0.0034052813167596845,5e-05
,58.9999988142802,39.999999323998274,0.0035089698804245126,5e-05
,59.999997601767134,40.00000059624428,0.003430200370654559,5e-05
,61.000000513052136,39.99999940162683,0.003259705315420825,5e-05
,61.99999970241596,40.00000076711854,0.0033041661170662424,5e-05
,62.999999469991586,40.00000239168453,0.003195497874433528,5e-05
,63.99999976384537,39.99999831384746,0.003127369873721573,5e-05
,65.00000181647594,39.99999924779562,0.0030734876536662255,5e-05
,65.99999995019903,40.00000112014618,0.002898118235670351,5e-05
,67.00000008661927,39.99999985492183,0.002876301954046462,5e-05
,67.99999851292714,40.00000116108985,0.0027775300982397686,5e-05
,69.00000164733906,39.999998989935726,0.0026819278706634747,5e-05
,70.00000091748798,40.000000331344175,0.002624575354847466,5e-05
,71.00000106693487,39.99999984944368,0.0024736602136746265,5e-05
,72.00000004767273,40.00000014037072,0.002310210674013892,5e-05
,73.00000091665478,40.00000033111602,0.0023259699707565006,5e-05
,74.00000037094684,39.99999877999364,0.0020791925723746257,5e-05
,75.00000061318907,39.99999892586251,0.0020111854318846174,5e-05
,75.99999984780705,40.000001399244006,0.0018875844212373723,5e-05
,76.99999852611205,40.00000029321371,0.0018342973070046306,5e-05
,78.00000102885434,40.000000106346334,0.0017996810950882448,5e-05
,78.99999806504036,39.999999955925276,0.0017194137389938333,5e-05
,79.99999976006333,40.0000003565425,0.001589731741746052,5e-05
,80.9999997954775,39.99999884406326,0.00145139856883898,5e-05
,81.99999895713987,39.99999900097267,0.0013729318015526413,5e-05
,83.00000061312313,40.000001304508245,0.0012927325572316042,5e-05
,83.99999979967029,40.00000015127522,0.0012964054248229796,5e-05
,84.99999956313168,40.00000085030087,0.0011329141014788178,5e-05
,86.00000051984173,39.999999394335994,0.0011545299473498085,5e-05
,86.99999952342095,40.00000137672538,0.0010462675427337672,5e-05
,88.00000138897998,40.00000034527841,0.0009965434546215291,5e-05
,89.00000035145507,40.00000048124582,0.0010069172011742198,5e-05
,89.99999952566701,40.00000054872934,0.0008541807271680578,5e-05
,90.99999805573502,39.99999920299076,0.0009107415388861817,5e-05
,91.9999986922468,39.99999813427914,0.0007098382083966987,5e-05
,93.00000108683078,39.99999892519733,0.0006945272971541864,5e-05
,93.99999994939594,40.00000163052286,0.0006149478051893053,5e-05
,94.99999971687494,40.00000130068397,0.0006171259441238826,5e-05
,96.00000164325161,39.99999965307863,0.000646553489615632,5e-05
,96.99999871735075,39.99999969832367,0.0006194419650790972,5e-05
,97.9999994143422,40.00000103660588,0.0005651028400189633,5e-05
,98.99999952741233,39.999999831590124,0.0005322568863562772,5e-05
,100.00000058633728,39.99999870074013,0.00043117824670160597,5e-05
,0.9999993364648017,60.00000126554309,0.005827671602717364,5e-05
,1.9999993865821515,60.00000047717858,0.00590314193738526,5e-05
,2.999998394850603,59.99999748366029,0.005949014534197689,5e-05
,4.000000729349404,59.99999968680989,0.005856844660872581,5e-05
,5.000000806139359,60.000000143670206,0.0058048133588465166,5e-05
,5.999999523623252,60.00000048124683,0.005784547153905366,5e-05
,7.000000163339945,60.00000015215119,0.005819951010010103,5e-05
,7.999998707353877,59.9999993642582,0.005925564560040568,5e-05
,8.999999528186846,59.99999988424096,0.005828670918339856,5e-05
,10.000001377950953,60.000000294800316,0.00577954047259579,5e-05
,11.000000135730733,59.99999973199591,0.005793302927092588,5e-05
,12.000002310363486,59.99999962809928,0.005791954554069057,5e-05
,12.999999212807257,60.00000125208394,0.005821849257904547,5e-05
,14.000000580284416,59.999999053392315,0.005768158178872685,5e-05
,14.999999804494172,59.99999965053653,0.0057494848922105424,5e-05
,16.000000565817846,59.99999796873099,0.005777720889555337,5e-05
,16.99999999278864,60.000000540969964,0.005804101073297145,5e-05
,17.99999943880189,60.00000082826446,0.005810563149500292,5e-05
,18.999999132383234,60.00000054848683,0.005796870705847592,5e-05
,20.00000306603674,60.00000091767249,0.00574178220052603,5e-05
,20.99999992265494,60.00000044070674,0.005675980837604098,5e-05
,21.99999798333931,60.00000034251539,0.005717727483472749,5e-05
,22.999999351399392,60.00000047394707,0.0057696806804373784,5e-05
,24.000000678039726,59.99999973269157,0.005687569961313562,5e-05
,24.999999499991567,60.000001188327865,0.0057666355897943,5e-05
,26.000001360446202,59.999999651427935,0.005725236917517607,5e-05
,27.000001002398275,59.999998537648075,0.005727307087963392,5e-05
,27.999999847661364,60.00000084978361,0.005814954575222984,5e-05
,28.99999952778406,60.00000185070278,0.005773261648670542,5e-05
,29.999998995198993,59.99999903984888,0.005834821091715947,5e-05
,30.99999930003346,59.99999989836887,0.005723777363880363,5e-05
,31.999998526856924,59.99999931455799,0.005831921740528903,5e-05
,33.00000120439629,59.99999961941675,0.005825413417626476,5e-05
,34.00000159070079,60.00000004609297,0.005634384117473334,5e-05
,34.99999874386193,59.999998758191545,0.005783120454879345,5e-05
,35.999998818317025,59.99999972234633,0.005866852230757301,5e-05
,36.99999823148814,59.99999853403261,0.0058292027465624546,5e-05
,37.999999036145766,59.99999943177236,0.005766657133896019,5e-05
,38.9999968936632,59.99999881393035,0.005772859313211025,5e-05
,39.999998857721046,59.9999989409393,0.005711945999940047,5e-05
,41.0000012969154,59.99999828008932,0.005776301576457843,5e-05
,41.99999965432747,60.00000121935459,0.005660974401231852,5e-05
,43.000000854584236,60.000000509059085,0.005679754556711914,5e-05
,43.999999511030936,59.99999808253596,0.005761115039743014,5e-05
,45.000001760667296,59.9999994031724,0.005673061849774348,5e-05
,46.000000199217986,59.9999993295614,0.005618742668025684,5e-05
,46.99999961799771,59.99999930905587,0.005587985115945989,5e-05
,48.00000255242403,59.99999855311649,0.005680004195299099,5e-05
,48.999999675528144,60.000000754385724,0.005537353851230905,5e-05
,49.99999877877665,59.999999604136214,0.005382428286682561,5e-05
,51.000000201910005,60.00000046814891,0.005433054560588508,5e-05
,51.99999996116496,60.00000052675576,0.005266722072330529,5e-05
,53.00000106632455,60.000001375445315,0.005222665250797647,5e-05
,53.99999907836607,59.99999818512772,0.005064158905204387,5e-05
,55.00000080471693,60.00000173860211,0.004948004681349515,5e-05
,56.00000085274847,60.000001268815275,0.004930375111582074,5e-05
,56.99999933231271,60.00000057306599,0.004741639983644283,5e-05
,58.000000163244,60.00000238359223,0.004625754213780698,5e-05
,58.99999916924804,60.0000002049786,0.004589936990639192,5e-05
,60.00000234580807,60.00000082147891,0.004363254279692833,5e-05
,60.99999929586044,59.99999926158602,0.004223421118703773,5e-05
,61.99999954692556,60.000001134357404,0.004192019071852817,5e-05
,62.99999893416198,60.00000016782597,0.003935160298695232,5e-05
,63.999999653878724,59.999999548799856,0.0038626051285023375,5e-05
,64.99999999412397,60.0000021169392,0.003748223575298339,5e-05
,66.00000076778913,59.99999969520034,0.0035654366379882997,5e-05
,66.99999938951335,60.00000000886133,0.0034434822625290062,5e-05
,67.99999981422604,59.99999980272004,0.003400282229467166,5e-05
,68.99999858351063,59.99999924432909,0.003250724314904077,5e-05
,69.99999917259777,60.0000005312724,0.003059846880537245,5e-05
,71.00000275580756,60.000000738409604,0.003006946330264936,5e-05
,72.0000010412432,60.000000354372524,0.0029324239679561557,5e-05
,72.99999921857597,59.999997639421736,0.002671263683145242,5e-05
,73.99999866260276,60.00000100799701,0.0026205462428750847,5e-05
,74.99999902441716,59.99999964976165,0.0026017788145885528,5e-05
,75.99999997830913,59.99999878367659,0.002422475090506193,5e-05
,77.00000003472779,60.00000060328096,0.0023251674032294684,5e-05
,77.9999992556394,60.00000056284942,0.0021707457794256486,5e-05
,78.99999871342553,59.9999989569263,0.0020408147096148354,5e-05
,80.0000014223785,60.00000247243568,0.002041545423173133,5e-05
,81.00000045168545,59.99999879037345,0.00192440618548929,5e-05
,81.99999962543198,59.999998266997295,0.0018001193077988229,5e-05
,82.9999997793388,59.99999884582857,0.0016939723615085741,5e-05
,83.99999947046955,60.00000142079984,0.0015478864909793993,5e-05
,84.99999706395455,59.99999982414327,0.001564502670896486,5e-05
,86.00000011566183,59.99999962794331,0.001446860603340586,5e-05
,86.99999892945559,59.999999937842276,0.001402794657661575,5e-05
,87.9999989973157,59.99999940338609,0.0013739743136917078,5e-05
,88.9999993597376,59.99999930973659,0.0013154542758729306,5e-05
,90.00000073230171,59.99999935878451,0.0012473165844899751,5e-05
,90.99999882946919,60.00000070795552,0.001263810425598243,5e-05
,91.99999856571854,60.00000102045588,0.001151678492910927,5e-05
,93.00000063985208,59.99999894490744,0.0010010576240940092,5e-05
,94.0000007543689,60.00000023922797,0.0009448608418763226,5e-05
,94.99999904106629,60.00000078820724,0.0010519782773215896,5e-05
,96.00000056239767,59.99999891824805,0.0008544878172294979,5e-05
,96.99999970836757,59.99999949743341,0.0008397307267899229,5e-05
,98.00000030129218,59.99999896193584,0.0008855783519479725,5e-05
,98.99999873903973,59.999998708971454,0.0008425312050404464,5e-05
,100.00000083289444,60.00000010186287,0.0007144163848107992,5e-05
,1.000001203258954,79.99999926386762,0.007881240381828723,5e-05
,2.0000006370732355,80.00000063112908,0.007781580672339445,5e-05
,3.000000558339962,79.99999997057807,0.007812177672834002,5e-05
,3.9999962277248438,80.00000041262736,0.00783371982895812,5e-05
,5.000000260629749,79.99999970771708,0.007846286205360455,5e-05
,5.999999974554683,79.99999936500262,0.007825265415236338,5e-05
,6.999999852954494,79.99999990932686,0.007844267500815273,5e-05
,7.99999936942201,79.99999999500388,0.007941956947558448,5e-05
,9.000000055364975,79.9999992941445,0.00785174802952709,5e-05
,10.000000412117405,80.00000042659545,0.007840809718290988,5e-05
,10.999999736211839,80.00000074659485,0.00782303705545503,5e-05
,11.99999953667586,80.0000001580827,0.00781274022709533,5e-05
,13.000001229753812,80.00000171349089,0.007882275169681926,5e-05
,13.999998894632892,79.99999936766099,0.007771333450563363,5e-05
,15.000001030155198,80.00000052059642,0.007815921936223765,5e-05
,16.000000176812463,79.9999995912652,0.007769793229213029,5e-05
,16.999999195694354,80.00000023462951,0.007832414387250342,5e-05
,17.999999710018106,79.99999917005066,0.007838570924771944,5e-05
,18.999999080006397,80.00000111512338,0.007884246613027366,5e-05
,20.00000067506452,80.0000001760209,0.007904670514790886,5e-05
,21.00000034790176,80.0000011922445,0.007885350152382705,5e-05
,21.999999443203826,79.99999873390442,0.00794139857135561,5e-05
,22.9999988977817,79.99999950648478,0.007948267416360325,5e-05
,24.000000301716092,79.9999991074342,0.007893374785314097,5e-05
,25.000000957385605,79.99999946805814,0.007904937149688044,5e-05
,25.99999988616365,79.9999993073903,0.007797658343875445,5e-05
,27.0000004183525,79.99999987945907,0.007917820892363547,5e-05
,27.99999962397285,79.99999998275285,0.007907574069912044,5e-05
,29.000000067569207,79.99999995901514,0.007827617899549388,5e-05
,29.999999708717088,79.99999944447613,0.007892358562327078,5e-05
,31.00000029404214,80.00000018742517,0.007960806554484995,5e-05
,31.999998490227487,80.0000008756155,0.007846560128744172,5e-05
,33.00000064419052,79.99999909772444,0.007964691851198693,5e-05
,33.99999977006752,80.00000000088862,0.007910740333094463,5e-05
,35.00000035860807,79.99999992592912,0.00785739002515061,5e-05
,35.99999965968987,80.00000046835463,0.007837822399268463,5e-05
,37.00000032036119,79.99999993614142,0.007856388067177174,5e-05
,37.9999989274372,79.99999998433519,0.0077066486798882975,5e-05
,39.00000118915441,79.99999900890421,0.007836563765116671,5e-05
,39.99999829645541,80.00000002170384,0.007642815052702883,5e-05
,40.99999896076118,79.99999907811551,0.007586580989792144,5e-05
,42.00000023566607,80.00000051570424,0.007619466253197292,5e-05
,43.000001462842285,79.99999989678106,0.007523644829529327,5e-05
,44.0000002781263,80.00000003985842,0.007468251516408355,5e-05
,44.99999975209155,79.99999910880963,0.007364325575469101,5e-05
,45.99999857490986,80.00000080375759,0.007233259475725212,5e-05
,46.99999980872334,80.0000006923139,0.007045646501113932,5e-05
,47.999999980122986,80.00000086152393,0.0069737822099993005,5e-05
,49.000001690568645,80.00000222738608,0.00688862515701215,5e-05
,50.00000062212522,79.99999994748062,0.006752891791785959,5e-05
,50.99999847090712,80.00000120340283,0.006520427560119499,5e-05
,52.00000202677909,79.9999998761722,0.006539411215339582,5e-05
,52.99999960499012,80.0000003940873,0.006433251987907983,5e-05
,53.99999912054029,80.00000036533743,0.006275374799117841,5e-05
,55.00000147482265,80.00000026459176,0.006003325262142003,5e-05
,55.99999995024424,80.00000065825618,0.005925240077879375,5e-05
,56.9999996325974,79.99999969606363,0.005644109406454901,5e-05
,58.00000021878599,80.00000004093228,0.0056802741440854,5e-05
,59.00000084488878,80.00000053530965,0.005343018496467837,5e-05
,60.00000099333621,80.0000017478539,0.005304201672063803,5e-05
,60.9999986247976,79.99999915764333,0.005185384763715211,5e-05
,62.00000199848147,79.99999819386738,0.00503577090215949,5e-05
,63.00000094686159,79.99999951591451,0.004833136588325874,5e-05
,63.99999962079894,80.00000008992843,0.00459054765065629,5e-05
,64.99999918134014,80.00000017497709,0.004504156885235259,5e-05
,65.99999903098757,80.00000009221779,0.004344974166618477,5e-05
,67.00000012337844,80.00000118279013,0.004228029345103445,5e-05
,67.9999993519837,80.00000097604979,0.004112489603969894,5e-05
,68.99999923512604,79.99999995073209,0.003952155025435406,5e-05
,70.00000081125441,79.99999953045288,0.0038837047003253593,5e-05
,71.00000036456734,79.99999965399113,0.003672001347170779,5e-05
,71.99999960542874,79.99999964369584,0.003483697164548039,5e-05
,73.00000073424759,79.99999977440052,0.0034517802311517785,5e-05
,74.00000136737863,79.99999842734944,0.003224723929839873,5e-05
,74.99999890550369,79.99999953895926,0.0031277951213544673,5e-05
,75.99999939670812,79.99999957511997,0.0029991187220744842,5e-05
,77.00000094262184,79.99999981111961,0.0027549551916058374,5e-05
,78.00000071894057,79.99999974569998,0.002766177260753414,5e-05
,79.00000022669886,80.00000067200715,0.002652725954722828,5e-05
,80.00000116242119,79.99999946805664,0.0025168934061274304,5e-05
,80.99999891178827,79.9999995614223,0.0024126488705223685,5e-05
,81.99999852086216,80.00000054193876,0.0022510349612251657,5e-05
,82.99999913349264,79.99999976468516,0.002218120145914663,5e-05
,84.0000001225441,80.00000021645472,0.002191072951345666,5e-05
,84.99999920391322,80.0000006693357,0.0020121641890544608,5e-05
,85.99999951278184,80.00000042196949,0.001903172711105646,5e-05
,86.99999902499988,80.00000025016244,0.0018102689172380078,5e-05
,87.99999937957085,79.99999980355844,0.0018559815062897137,5e-05
,88.99999899521278,80.00000068189411,0.0016048981048960606,5e-05
,90.0000003674662,80.00000017554994,0.0016354641055294976,5e-05
,91.00000079489106,79.99999949514725,0.0015223242452974627,5e-05
,91.99999951955407,79.99999984919081,0.001539269628439543,5e-05
,92.9999997927342,79.99999878187062,0.0014381427874364094,5e-05
,93.99999941896743,79.99999903844403,0.001300347539501574,5e-05
,95.00000053125122,79.99999811709196,0.0011626452516460925,5e-05
,96.00000008905604,79.99999932006862,0.0012488660507247672,5e-05
,97.0000015941569,80.00000133554542,0.0011905975727721963,5e-05
,97.99999890452797,79.99999944351116,0.0010053407337751606,5e-05
,99.0000003625025,80.00000078754081,0.0010432479010091416,5e-05
,100.0000004439914,79.99999999655014,0.0009137871090230216,5e-05
,0.999999639559829,99.99999929945118,0.00984350490908297,5e-05
,2.0000005835341272,100.00000133827952,0.00980203811819973,5e-05
,2.999998561477351,100.00000058220584,0.00993025802415749,5e-05
,4.000002118803031,99.99999824819943,0.00989929391500503,5e-05
,4.999998657955547,100.0000010414022,0.009913691750443238,5e-05
,6.000000919807261,99.9999989252085,0.00996600192346592,5e-05
,6.999998878877321,99.99999982208605,0.009932465210881189,5e-05
,8.000001150883032,100.00000066811342,0.009935204734086123,5e-05
,8.999999615225974,99.99999970014684,0.009951687669644332,5e-05
,10.000000158422907,100.00000111894406,0.009870536272131365,5e-05
,11.000000053343756,100.00000076126376,0.009932830904007752,5e-05
,12.000001100734096,99.9999984231244,0.009886195424469887,5e-05
,12.99999967845255,99.99999952756585,0.00991450660451622,5e-05
,13.99999703281629,100.00000028207373,0.009968773297996475,5e-05
,14.99999923994121,99.99999942500132,0.01004096883097595,5e-05
,16.000000183712324,99.9999997837235,0.010105674265617067,5e-05
,16.999999559531794,100.00000079978491,0.009963451494399905,5e-05
,18.00000076982085,100.00000031678131,0.010041013410911785,5e-05
,19.000001015326998,99.99999907938097,0.010042706894308896,5e-05
,19.99999985222819,100.00000017460637,0.010085326482023597,5e-05
,20.999998510354605,99.99999938773037,0.0100991013298402,5e-05
,22.00000138416511,99.99999878480764,0.010096885266755543,5e-05
,23.0000010830535,99.99999886994415,0.010036393153520718,5e-05
,23.999999700808864,100.00000028695554,0.010107097496772459,5e-05
,25.00000210828841,99.9999999718863,0.010130627376441048,5e-05
,25.99999965112454,100.00000000543181,0.01005443835302522,5e-05
,26.99999886288028,99.99999885379096,0.010167989681030271,5e-05
,27.999999844126567,99.99999981607046,0.010040637291726655,5e-05
,29.000001077833716,99.9999989628324,0.009997805656936849,5e-05
,29.999999062546557,99.99999907360616,0.010014778986932892,5e-05
,31.000001951225077,99.99999983487324,0.0099504737313377,5e-05
,31.999999103473787,99.99999861660955,0.009850968731089085,5e-05
,33.000000954422276,100.00000066926727,0.009866293883333072,5e-05
,34.000000544462374,100.00000248688285,0.009887755901823744,5e-05
,34.99999984594294,100.00000045882325,0.009840434568894453,5e-05
,36.00000108053298,99.99999895709686,0.009636215137615268,5e-05
,36.99999850020121,99.99999972881449,0.009626046558233977,5e-05
,38.00000135757179,99.99999844456205,0.009495693721058546,5e-05
,38.99999993631597,99.99999962238361,0.009403801486116088,5e-05
,39.99999945756475,100.00000050731394,0.009346026478453786,5e-05
,41.00000074917405,100.00000058938477,0.00921114021272694,5e-05
,42.00000105989901,99.99999896825724,0.00905533005265481,5e-05
,43.00000076979543,100.00000029914565,0.008873868281206579,5e-05
,44.00000199950382,100.00000115640802,0.008730862557733456,5e-05
,45.00000108072608,100.00000175509159,0.008645157493146918,5e-05
,46.000001283506634,99.99999929920511,0.0085208684944825,5e-05
,46.99999946013606,99.99999913579998,0.008381707097335782,5e-05
,48.00000010652378,100.00000005441586,0.008243535637794898,5e-05
,49.000000562982585,99.99999707190983,0.00809782030239804,5e-05
,49.99999998225776,99.999999468966,0.007770077369628348,5e-05
,51.00000030163523,99.99999972902503,0.007774229164713445,5e-05
,52.00000042610477,99.99999954065801,0.007513370236984859,5e-05
,53.00000084424392,99.99999841612677,0.00745638614695047,5e-05
,53.99999989839111,99.9999997544489,0.007251074372475267,5e-05
,54.999999650200785,99.99999922339138,0.007098282788055151,5e-05
,55.99999917168435,100.00000075748306,0.006871477859112279,5e-05
,56.99999910826767,99.99999908152519,0.006743957343162929,5e-05
,58.00000117245123,99.99999971765487,0.006467543857210409,5e-05
,58.99999991547851,99.99999976705207,0.0064467493420787515,5e-05
,60.00000078694438,100.00000056757142,0.006206733188200844,5e-05
,60.999998702636155,99.99999745409539,0.005925499920433809,5e-05
,61.99999806183189,99.99999965937506,0.005940268399736561,5e-05
,62.99999895090877,100.00000075961515,0.005803994357843098,5e-05
,64.00000114662697,99.99999963831176,0.0055101833976404025,5e-05
,65.00000106807744,99.99999847306303,0.005449478481837859,5e-05
,66.00000033203861,100.00000032659817,0.005187370227602004,5e-05
,66.99999919782985,100.00000033668691,0.004948850492525481,5e-05
,67.99999986919735,99.9999997295106,0.004883045492981632,5e-05
,68.99999970223952,99.9999988402043,0.004757597939846535,5e-05
,69.99999965502666,99.99999925932485,0.004590050577297394,5e-05
,70.99999749393017,99.99999968624348,0.0044325103251817285,5e-05
,71.99999914207362,99.99999912446714,0.004288129759488324,5e-05
,72.99999980989112,99.99999807982165,0.004132280584823695,5e-05
,74.00000151642779,99.9999992307132,0.003961105222907166,5e-05
,75.00000016074306,99.99999993825607,0.0037947444754733452,5e-05
,76.00000140088828,99.99999949293993,0.0036670203633330607,5e-05
,76.99999960629309,99.99999992442716,0.0035209475990633614,5e-05
,77.99999974731142,100.00000008365798,0.003384457156207696,5e-05
,78.99999610057827,100.0000008965755,0.0032084986762818124,5e-05
,80.00000046333034,100.00000220382412,0.003103641743593797,5e-05
,81.00000054709567,100.00000073177884,0.00300519122811486,5e-05
,82.00000176375907,99.99999859567146,0.0028901332779968304,5e-05
,82.99999951323879,99.99999734305506,0.002748396478187711,5e-05
,84.00000009415416,99.99999990553783,0.0026227709861368635,5e-05
,84.99999929447205,100.00000007138844,0.002542507986823048,5e-05
,85.99999882374294,99.9999988381267,0.0024438584209052283,5e-05
,86.99999928689203,100.00000027203214,0.002328036528268294,5e-05
,87.99999965500147,99.99999923306041,0.002101000451411817,5e-05
,89.00000135543803,100.00000040266973,0.0020637606362933227,5e-05
,90.0000000022116,99.99999967448183,0.0020234144628406225,5e-05
,90.9999992094552,100.00000039746259,0.0019190515460468533,5e-05
,92.00000014187783,99.9999982568048,0.0018359441464773233,5e-05
,93.00000021757135,99.99999956153313,0.0017298283530168045,5e-05
,93.99999932376794,99.999999851404,0.0015870306657510985,5e-05
,95.00000114323363,99.99999857512528,0.001609818272690074,5e-05
,95.99999811165111,100.00000188233825,0.0014030179155225275,5e-05
,96.99999978645538,99.99999945922659,0.001445849830497337,5e-05
,98.00000066506607,100.00000138997173,0.001324491875471854,5e-05
,98.99999866156747,99.9999993356579,0.0011835327009932393,5e-05
,100.00000036125375,99.99999977002885,0.0011722362255320187,5e-05